<?xml version="1.0" encoding="utf-8"?>
<!-- This URDF was automatically created by SolidWorks to URDF Exporter! Originally created by Stephen Brawner (brawner@gmail.com) 
     Commit Version: 1.6.0-4-g7f85cfe  Build Version: 1.6.7995.38578
     For more information, please see http://wiki.ros.org/sw_urdf_exporter -->
<robot
  name="testbot">
  <link
    name="body">
    <inertial>
      <origin
        xyz="0.008033 0 0.061122"
        rpy="0 0 0" />
      <mass
        value="3.7018" />
      <inertia
        ixx="0.051875"
        ixy="-3.0668E-18"
        ixz="-0.0039007"
        iyy="0.051099"
        iyz="1.6318E-18"
        izz="0.085386" />
    </inertial>
    <visual>
      <origin
        xyz="0 0 0"
        rpy="0 0 0" />
      <geometry>
        <mesh
          filename="package://testbot/meshes/body.STL" />
      </geometry>
      <material
        name="">
        <color
          rgba="0.79216 0.81961 0.93333 1" />
      </material>
    </visual>
    <collision>
      <origin
        xyz="0 0 0"
        rpy="0 0 0" />
      <geometry>
        <mesh
          filename="package://testbot/meshes/body.STL" />
      </geometry>
    </collision>
  </link>
  <link
    name="front_left_wheel">
    <inertial>
      <origin
        xyz="2.58248119305859E-07 0.0103100232964128 -1.21013738418885E-07"
        rpy="0 0 0" />
      <mass
        value="0.0297341392937907" />
      <inertia
        ixx="1.22910761029336E-05"
        ixy="8.10842359195753E-11"
        ixz="1.14908676285921E-10"
        iyy="2.03788335831534E-05"
        iyz="-3.82165615196521E-11"
        izz="1.22913469876392E-05" />
    </inertial>
    <visual>
      <origin
        xyz="0 0 0"
        rpy="0 0 0" />
      <geometry>
        <mesh
          filename="package://testbot/meshes/front_left_wheel.STL" />
      </geometry>
      <material
        name="">
        <color
          rgba="0.298039215686275 0.298039215686275 0.298039215686275 1" />
      </material>
    </visual>
    <collision>
      <origin
        xyz="0 0 0"
        rpy="0 0 0" />
      <geometry>
        <mesh
          filename="package://testbot/meshes/front_left_wheel.STL" />
      </geometry>
    </collision>
  </link>
  <joint
    name="front_left_wheel"
    type="continuous">
    <origin
      xyz="-0.073 0.09815 -0.014"
      rpy="0 0 -3.1416" />
    <parent
      link="body" />
    <child
      link="front_left_wheel" />
    <axis
      xyz="0 -1 0" />
    <limit
      effort="1"
      velocity="1" />
  </joint>
  <link
    name="front_right_wheel">
    <inertial>
      <origin
        xyz="-2.58248114476389E-07 0.0103100232964129 1.21013735893127E-07"
        rpy="0 0 0" />
      <mass
        value="0.0297341392937916" />
      <inertia
        ixx="1.22910761029339E-05"
        ixy="-8.10842360907973E-11"
        ixz="1.14908676207216E-10"
        iyy="2.03788335831539E-05"
        iyz="3.82165616106154E-11"
        izz="1.22913469876395E-05" />
    </inertial>
    <visual>
      <origin
        xyz="0 0 0"
        rpy="0 0 0" />
      <geometry>
        <mesh
          filename="package://testbot/meshes/front_right_wheel.STL" />
      </geometry>
      <material
        name="">
        <color
          rgba="0.298039215686275 0.298039215686275 0.298039215686275 1" />
      </material>
    </visual>
    <collision>
      <origin
        xyz="0 0 0"
        rpy="0 0 0" />
      <geometry>
        <mesh
          filename="package://testbot/meshes/front_right_wheel.STL" />
      </geometry>
    </collision>
  </link>
  <joint
    name="front_right_wheel"
    type="continuous">
    <origin
      xyz="-0.073 -0.09815 -0.014"
      rpy="0 0 0" />
    <parent
      link="body" />
    <child
      link="front_right_wheel" />
    <axis
      xyz="0 1 0" />
    <limit
      effort="1"
      velocity="1" />
  </joint>
  <link
    name="rear_left_wheel">
    <inertial>
      <origin
        xyz="-2.43694072699085E-08 -0.0103100232964135 -2.84152328666742E-07"
        rpy="0 0 0" />
      <mass
        value="0.0297341392937934" />
      <inertia
        ixx="1.22913787607802E-05"
        ixy="7.46016441292797E-12"
        ixz="-5.98966931947386E-11"
        iyy="2.0378833583155E-05"
        iyz="8.93280740814802E-11"
        izz="1.22910443297946E-05" />
    </inertial>
    <visual>
      <origin
        xyz="0 0 0"
        rpy="0 0 0" />
      <geometry>
        <mesh
          filename="package://testbot/meshes/rear_left_wheel.STL" />
      </geometry>
      <material
        name="">
        <color
          rgba="0.298039215686275 0.298039215686275 0.298039215686275 1" />
      </material>
    </visual>
    <collision>
      <origin
        xyz="0 0 0"
        rpy="0 0 0" />
      <geometry>
        <mesh
          filename="package://testbot/meshes/rear_left_wheel.STL" />
      </geometry>
    </collision>
  </link>
  <joint
    name="rear_left_wheel"
    type="continuous">
    <origin
      xyz="0.073 0.09815 -0.014"
      rpy="0 0 0" />
    <parent
      link="body" />
    <child
      link="rear_left_wheel" />
    <axis
      xyz="0 -1 0" />
    <limit
      effort="1"
      velocity="1" />
  </joint>
  <link
    name="rear_right_wheel">
    <inertial>
      <origin
        xyz="0 0 0"
        rpy="0 0 0" />
      <mass
        value="0" />
      <inertia
        ixx="0"
        ixy="0"
        ixz="0"
        iyy="0"
        iyz="0"
        izz="0" />
    </inertial>
    <visual>
      <origin
        xyz="0 0 0"
        rpy="0 0 0" />
      <geometry>
        <mesh
          filename="package://testbot/meshes/rear_right_wheel.STL" />
      </geometry>
      <material
        name="">
        <color
          rgba="1 1 1 1" />
      </material>
    </visual>
    <collision>
      <origin
        xyz="0 0 0"
        rpy="0 0 0" />
      <geometry>
        <mesh
          filename="package://testbot/meshes/rear_right_wheel.STL" />
      </geometry>
    </collision>
  </link>
  <joint
    name="rear_right_wheel"
    type="continuous">
    <origin
      xyz="0.073 -0.09815 -0.014"
      rpy="0 0 0" />
    <parent
      link="body" />
    <child
      link="rear_right_wheel" />
    <axis
      xyz="0 -1 0" />
    <limit
      effort="1"
      velocity="1" />
  </joint>
</robot>